Main: Using 8 CUDA GPU(s) for DDP.
Main: Spawning 8 DDP processes...
[rank4]:[W519 02:12:40.456331109 ProcessGroupNCCL.cpp:4715] [PG ID 0 PG GUID 0 Rank 4]  using GPU 4 as device used by this process is currently unknown. This can potentially cause a hang if this rank to GPU mapping is incorrect. You can pecify device_id in init_process_group() to force use of a particular device.
[rank7]:[W519 02:12:40.538233496 ProcessGroupNCCL.cpp:4715] [PG ID 0 PG GUID 0 Rank 7]  using GPU 7 as device used by this process is currently unknown. This can potentially cause a hang if this rank to GPU mapping is incorrect. You can pecify device_id in init_process_group() to force use of a particular device.
[rank2]:[W519 02:12:40.595827445 ProcessGroupNCCL.cpp:4715] [PG ID 0 PG GUID 0 Rank 2]  using GPU 2 as device used by this process is currently unknown. This can potentially cause a hang if this rank to GPU mapping is incorrect. You can pecify device_id in init_process_group() to force use of a particular device.
[rank3]:[W519 02:12:40.666696464 ProcessGroupNCCL.cpp:4715] [PG ID 0 PG GUID 0 Rank 3]  using GPU 3 as device used by this process is currently unknown. This can potentially cause a hang if this rank to GPU mapping is incorrect. You can pecify device_id in init_process_group() to force use of a particular device.
[rank6]:[W519 02:12:40.847413725 ProcessGroupNCCL.cpp:4715] [PG ID 0 PG GUID 0 Rank 6]  using GPU 6 as device used by this process is currently unknown. This can potentially cause a hang if this rank to GPU mapping is incorrect. You can pecify device_id in init_process_group() to force use of a particular device.
[rank1]:[W519 02:12:40.951946636 ProcessGroupNCCL.cpp:4715] [PG ID 0 PG GUID 0 Rank 1]  using GPU 1 as device used by this process is currently unknown. This can potentially cause a hang if this rank to GPU mapping is incorrect. You can pecify device_id in init_process_group() to force use of a particular device.
[rank5]:[W519 02:12:40.056812983 ProcessGroupNCCL.cpp:4715] [PG ID 0 PG GUID 0 Rank 5]  using GPU 5 as device used by this process is currently unknown. This can potentially cause a hang if this rank to GPU mapping is incorrect. You can pecify device_id in init_process_group() to force use of a particular device.
[rank0]:[W519 02:12:40.071805441 ProcessGroupNCCL.cpp:4715] [PG ID 0 PG GUID 0 Rank 0]  using GPU 0 as device used by this process is currently unknown. This can potentially cause a hang if this rank to GPU mapping is incorrect. You can pecify device_id in init_process_group() to force use of a particular device.
DDP: Initializing process group for rank 0/8...
Rank 0 using device: 0
Rank 0: Downloading MNIST dataset...
Rank 0: Download complete.

--- Rank 0: Training model with base_channels = 2 ---
Rank 0: Number of parameters: 3,022
Rank 0: Epoch 1/15 | Train Loss: 2.0875 | Test Loss: 1.8043 | Test Acc: 34.55%
Rank 0: Epoch 2/15 | Train Loss: 1.5586 | Test Loss: 1.3819 | Test Acc: 63.83%
Rank 0: Epoch 3/15 | Train Loss: 1.1162 | Test Loss: 1.0179 | Test Acc: 74.27%
Rank 0: Epoch 4/15 | Train Loss: 0.8151 | Test Loss: 0.7221 | Test Acc: 86.50%
Rank 0: Epoch 5/15 | Train Loss: 0.6055 | Test Loss: 0.5239 | Test Acc: 91.16%
Rank 0: Epoch 6/15 | Train Loss: 0.4607 | Test Loss: 0.3880 | Test Acc: 92.43%
Rank 0: Epoch 7/15 | Train Loss: 0.3635 | Test Loss: 0.3347 | Test Acc: 93.38%
Rank 0: Epoch 8/15 | Train Loss: 0.3027 | Test Loss: 0.2838 | Test Acc: 94.27%
Rank 0: Epoch 9/15 | Train Loss: 0.2603 | Test Loss: 0.2503 | Test Acc: 94.49%
Rank 0: Epoch 10/15 | Train Loss: 0.2301 | Test Loss: 0.1979 | Test Acc: 95.46%
Rank 0: Epoch 11/15 | Train Loss: 0.2071 | Test Loss: 0.1893 | Test Acc: 95.52%
Rank 0: Epoch 12/15 | Train Loss: 0.1900 | Test Loss: 0.1648 | Test Acc: 96.10%
Rank 0: Epoch 13/15 | Train Loss: 0.1779 | Test Loss: 0.1693 | Test Acc: 95.76%
Rank 0: Epoch 14/15 | Train Loss: 0.1666 | Test Loss: 0.1578 | Test Acc: 95.86%
Rank 0: Epoch 15/15 | Train Loss: 0.1547 | Test Loss: 0.1588 | Test Acc: 95.86%
Rank 0: Training for base_channels=2 took 540.56 seconds.
Rank 0: Model with base_channels=2 saved to checkpoints/double_descent/model_base_ch_2.pt

--- Rank 0: Training model with base_channels = 4 ---
Rank 0: Number of parameters: 11,442
Rank 0: Epoch 1/15 | Train Loss: 1.7707 | Test Loss: 1.3597 | Test Acc: 50.64%
Rank 0: Epoch 2/15 | Train Loss: 0.8217 | Test Loss: 1.0184 | Test Acc: 67.78%
Rank 0: Epoch 3/15 | Train Loss: 0.3862 | Test Loss: 0.3490 | Test Acc: 93.63%
Rank 0: Epoch 4/15 | Train Loss: 0.2334 | Test Loss: 0.1879 | Test Acc: 96.51%
Rank 0: Epoch 5/15 | Train Loss: 0.1656 | Test Loss: 0.1439 | Test Acc: 96.98%
Rank 0: Epoch 6/15 | Train Loss: 0.1286 | Test Loss: 0.1092 | Test Acc: 97.74%
Rank 0: Epoch 7/15 | Train Loss: 0.1065 | Test Loss: 0.0978 | Test Acc: 97.73%
Rank 0: Epoch 8/15 | Train Loss: 0.0909 | Test Loss: 0.0758 | Test Acc: 98.22%
Rank 0: Epoch 9/15 | Train Loss: 0.0802 | Test Loss: 0.0744 | Test Acc: 98.26%
Rank 0: Epoch 10/15 | Train Loss: 0.0711 | Test Loss: 0.0705 | Test Acc: 98.22%
Rank 0: Epoch 11/15 | Train Loss: 0.0646 | Test Loss: 0.0652 | Test Acc: 98.52%
Rank 0: Epoch 12/15 | Train Loss: 0.0594 | Test Loss: 0.0598 | Test Acc: 98.45%
Rank 0: Epoch 13/15 | Train Loss: 0.0538 | Test Loss: 0.0771 | Test Acc: 97.99%
Rank 0: Epoch 14/15 | Train Loss: 0.0516 | Test Loss: 0.0600 | Test Acc: 98.53%
Rank 0: Epoch 15/15 | Train Loss: 0.0481 | Test Loss: 0.0676 | Test Acc: 98.04%
Rank 0: Training for base_channels=4 took 549.56 seconds.
Rank 0: Model with base_channels=4 saved to checkpoints/double_descent/model_base_ch_4.pt

--- Rank 0: Training model with base_channels = 6 ---
Rank 0: Number of parameters: 25,270
Rank 0: Epoch 1/15 | Train Loss: 1.5948 | Test Loss: 0.9464 | Test Acc: 80.15%
Rank 0: Epoch 2/15 | Train Loss: 0.5159 | Test Loss: 0.4322 | Test Acc: 91.01%
Rank 0: Epoch 3/15 | Train Loss: 0.2032 | Test Loss: 0.1409 | Test Acc: 97.51%
Rank 0: Epoch 4/15 | Train Loss: 0.1228 | Test Loss: 0.1186 | Test Acc: 97.49%
Rank 0: Epoch 5/15 | Train Loss: 0.0868 | Test Loss: 0.0772 | Test Acc: 98.25%
Rank 0: Epoch 6/15 | Train Loss: 0.0692 | Test Loss: 0.0681 | Test Acc: 98.37%
Rank 0: Epoch 7/15 | Train Loss: 0.0571 | Test Loss: 0.0622 | Test Acc: 98.50%
Rank 0: Epoch 8/15 | Train Loss: 0.0496 | Test Loss: 0.0670 | Test Acc: 98.23%
Rank 0: Epoch 9/15 | Train Loss: 0.0420 | Test Loss: 0.0483 | Test Acc: 98.79%
Rank 0: Epoch 10/15 | Train Loss: 0.0371 | Test Loss: 0.0510 | Test Acc: 98.53%
Rank 0: Epoch 11/15 | Train Loss: 0.0337 | Test Loss: 0.0550 | Test Acc: 98.39%
Rank 0: Epoch 12/15 | Train Loss: 0.0313 | Test Loss: 0.0449 | Test Acc: 98.77%
Rank 0: Epoch 13/15 | Train Loss: 0.0278 | Test Loss: 0.0421 | Test Acc: 98.75%
Rank 0: Epoch 14/15 | Train Loss: 0.0256 | Test Loss: 0.0458 | Test Acc: 98.65%
Rank 0: Epoch 15/15 | Train Loss: 0.0243 | Test Loss: 0.0453 | Test Acc: 98.76%
Rank 0: Training for base_channels=6 took 547.80 seconds.
Rank 0: Model with base_channels=6 saved to checkpoints/double_descent/model_base_ch_6.pt

--- Rank 0: Training model with base_channels = 8 ---
Rank 0: Number of parameters: 44,506
Rank 0: Epoch 1/15 | Train Loss: 1.3304 | Test Loss: 0.9554 | Test Acc: 77.13%
Rank 0: Epoch 2/15 | Train Loss: 0.2782 | Test Loss: 0.3124 | Test Acc: 92.76%
Rank 0: Epoch 3/15 | Train Loss: 0.1193 | Test Loss: 0.1010 | Test Acc: 98.28%
Rank 0: Epoch 4/15 | Train Loss: 0.0783 | Test Loss: 0.0866 | Test Acc: 98.02%
Rank 0: Epoch 5/15 | Train Loss: 0.0591 | Test Loss: 0.1113 | Test Acc: 96.93%
Rank 0: Epoch 6/15 | Train Loss: 0.0477 | Test Loss: 0.0540 | Test Acc: 98.67%
Rank 0: Epoch 7/15 | Train Loss: 0.0401 | Test Loss: 0.0707 | Test Acc: 98.12%
Rank 0: Epoch 8/15 | Train Loss: 0.0359 | Test Loss: 0.2133 | Test Acc: 93.88%
Rank 0: Epoch 9/15 | Train Loss: 0.0306 | Test Loss: 0.0468 | Test Acc: 98.67%
Rank 0: Epoch 10/15 | Train Loss: 0.0266 | Test Loss: 0.0404 | Test Acc: 98.79%
Rank 0: Epoch 11/15 | Train Loss: 0.0250 | Test Loss: 0.0436 | Test Acc: 98.69%
Rank 0: Epoch 12/15 | Train Loss: 0.0229 | Test Loss: 0.0359 | Test Acc: 98.77%
Rank 0: Epoch 13/15 | Train Loss: 0.0214 | Test Loss: 0.0429 | Test Acc: 98.72%
Rank 0: Epoch 14/15 | Train Loss: 0.0208 | Test Loss: 0.0612 | Test Acc: 98.24%
Rank 0: Epoch 15/15 | Train Loss: 0.0170 | Test Loss: 0.0283 | Test Acc: 99.14%
Rank 0: Training for base_channels=8 took 543.87 seconds.
Rank 0: Model with base_channels=8 saved to checkpoints/double_descent/model_base_ch_8.pt

--- Rank 0: Training model with base_channels = 10 ---
Rank 0: Number of parameters: 69,150
Rank 0: Epoch 1/15 | Train Loss: 0.9703 | Test Loss: 0.3951 | Test Acc: 90.61%
Rank 0: Epoch 2/15 | Train Loss: 0.1481 | Test Loss: 0.1305 | Test Acc: 97.15%
Rank 0: Epoch 3/15 | Train Loss: 0.0769 | Test Loss: 0.0688 | Test Acc: 98.23%
Rank 0: Epoch 4/15 | Train Loss: 0.0552 | Test Loss: 0.0550 | Test Acc: 98.42%
Rank 0: Epoch 5/15 | Train Loss: 0.0417 | Test Loss: 0.0691 | Test Acc: 98.12%
Rank 0: Epoch 6/15 | Train Loss: 0.0357 | Test Loss: 0.0470 | Test Acc: 98.65%
Rank 0: Epoch 7/15 | Train Loss: 0.0293 | Test Loss: 0.0400 | Test Acc: 98.93%
Rank 0: Epoch 8/15 | Train Loss: 0.0250 | Test Loss: 0.0479 | Test Acc: 98.83%
Rank 0: Epoch 9/15 | Train Loss: 0.0215 | Test Loss: 0.0350 | Test Acc: 98.97%
Rank 0: Epoch 10/15 | Train Loss: 0.0192 | Test Loss: 0.0292 | Test Acc: 99.26%
Rank 0: Epoch 11/15 | Train Loss: 0.0170 | Test Loss: 0.0375 | Test Acc: 98.90%
Rank 0: Epoch 12/15 | Train Loss: 0.0156 | Test Loss: 0.0750 | Test Acc: 97.81%
Rank 0: Epoch 13/15 | Train Loss: 0.0153 | Test Loss: 0.0501 | Test Acc: 98.57%
Rank 0: Epoch 14/15 | Train Loss: 0.0118 | Test Loss: 0.0356 | Test Acc: 98.87%
Rank 0: Epoch 15/15 | Train Loss: 0.0103 | Test Loss: 0.0275 | Test Acc: 99.24%
Rank 0: Training for base_channels=10 took 542.74 seconds.
Rank 0: Model with base_channels=10 saved to checkpoints/double_descent/model_base_ch_10.pt

--- Rank 0: Training model with base_channels = 12 ---
Rank 0: Number of parameters: 99,202
Rank 0: Epoch 1/15 | Train Loss: 0.9158 | Test Loss: 0.2812 | Test Acc: 94.73%
Rank 0: Epoch 2/15 | Train Loss: 0.1227 | Test Loss: 0.0909 | Test Acc: 98.16%
Rank 0: Epoch 3/15 | Train Loss: 0.0637 | Test Loss: 0.0562 | Test Acc: 98.73%
Rank 0: Epoch 4/15 | Train Loss: 0.0445 | Test Loss: 0.0440 | Test Acc: 99.00%
Rank 0: Epoch 5/15 | Train Loss: 0.0326 | Test Loss: 0.0485 | Test Acc: 98.64%
Rank 0: Epoch 6/15 | Train Loss: 0.0274 | Test Loss: 0.0341 | Test Acc: 99.04%
Rank 0: Epoch 7/15 | Train Loss: 0.0229 | Test Loss: 0.0447 | Test Acc: 98.66%
Rank 0: Epoch 8/15 | Train Loss: 0.0186 | Test Loss: 0.0280 | Test Acc: 99.24%
Rank 0: Epoch 9/15 | Train Loss: 0.0161 | Test Loss: 0.0249 | Test Acc: 99.30%
Rank 0: Epoch 10/15 | Train Loss: 0.0137 | Test Loss: 0.0288 | Test Acc: 99.20%
Rank 0: Epoch 11/15 | Train Loss: 0.0118 | Test Loss: 0.0328 | Test Acc: 99.08%
Rank 0: Epoch 12/15 | Train Loss: 0.0109 | Test Loss: 0.0396 | Test Acc: 98.90%
Rank 0: Epoch 13/15 | Train Loss: 0.0106 | Test Loss: 0.0549 | Test Acc: 98.39%
Rank 0: Epoch 14/15 | Train Loss: 0.0104 | Test Loss: 0.0263 | Test Acc: 99.24%
Rank 0: Epoch 15/15 | Train Loss: 0.0098 | Test Loss: 0.0299 | Test Acc: 99.04%
Rank 0: Training for base_channels=12 took 489.85 seconds.
Rank 0: Model with base_channels=12 saved to checkpoints/double_descent/model_base_ch_12.pt

--- Rank 0: Training model with base_channels = 14 ---
Rank 0: Number of parameters: 134,662
Rank 0: Epoch 1/15 | Train Loss: 0.8227 | Test Loss: 0.1707 | Test Acc: 97.38%
Rank 0: Epoch 2/15 | Train Loss: 0.1027 | Test Loss: 0.1435 | Test Acc: 96.31%
Rank 0: Epoch 3/15 | Train Loss: 0.0569 | Test Loss: 0.0537 | Test Acc: 98.73%
Rank 0: Epoch 4/15 | Train Loss: 0.0394 | Test Loss: 0.0421 | Test Acc: 98.81%
Rank 0: Epoch 5/15 | Train Loss: 0.0311 | Test Loss: 0.0479 | Test Acc: 98.86%
Rank 0: Epoch 6/15 | Train Loss: 0.0260 | Test Loss: 0.0678 | Test Acc: 98.18%
Rank 0: Epoch 7/15 | Train Loss: 0.0209 | Test Loss: 0.0273 | Test Acc: 99.21%
Rank 0: Epoch 8/15 | Train Loss: 0.0171 | Test Loss: 0.0376 | Test Acc: 99.02%
Rank 0: Epoch 9/15 | Train Loss: 0.0154 | Test Loss: 0.0323 | Test Acc: 99.05%
Rank 0: Epoch 10/15 | Train Loss: 0.0131 | Test Loss: 0.0244 | Test Acc: 99.21%
Rank 0: Epoch 11/15 | Train Loss: 0.0110 | Test Loss: 0.1001 | Test Acc: 97.07%
Rank 0: Epoch 12/15 | Train Loss: 0.0100 | Test Loss: 0.0548 | Test Acc: 98.46%
Rank 0: Epoch 13/15 | Train Loss: 0.0097 | Test Loss: 0.0445 | Test Acc: 98.66%
Rank 0: Epoch 14/15 | Train Loss: 0.0085 | Test Loss: 0.0461 | Test Acc: 98.58%
Rank 0: Epoch 15/15 | Train Loss: 0.0062 | Test Loss: 0.0356 | Test Acc: 98.91%
Rank 0: Training for base_channels=14 took 483.94 seconds.
Rank 0: Model with base_channels=14 saved to checkpoints/double_descent/model_base_ch_14.pt

--- Rank 0: Training model with base_channels = 16 ---
Rank 0: Number of parameters: 175,530
Rank 0: Epoch 1/15 | Train Loss: 0.6972 | Test Loss: 0.5655 | Test Acc: 82.87%
Rank 0: Epoch 2/15 | Train Loss: 0.0882 | Test Loss: 0.1136 | Test Acc: 97.03%
Rank 0: Epoch 3/15 | Train Loss: 0.0523 | Test Loss: 0.0746 | Test Acc: 97.94%
Rank 0: Epoch 4/15 | Train Loss: 0.0376 | Test Loss: 0.0611 | Test Acc: 98.37%
Rank 0: Epoch 5/15 | Train Loss: 0.0290 | Test Loss: 0.0549 | Test Acc: 98.37%
Rank 0: Epoch 6/15 | Train Loss: 0.0236 | Test Loss: 0.0643 | Test Acc: 98.10%
Rank 0: Epoch 7/15 | Train Loss: 0.0192 | Test Loss: 0.0362 | Test Acc: 98.90%
Rank 0: Epoch 8/15 | Train Loss: 0.0175 | Test Loss: 0.0440 | Test Acc: 98.68%
Rank 0: Epoch 9/15 | Train Loss: 0.0126 | Test Loss: 0.0234 | Test Acc: 99.25%
Rank 0: Epoch 10/15 | Train Loss: 0.0102 | Test Loss: 0.0264 | Test Acc: 99.13%
Rank 0: Epoch 11/15 | Train Loss: 0.0094 | Test Loss: 0.0269 | Test Acc: 99.18%
Rank 0: Epoch 12/15 | Train Loss: 0.0107 | Test Loss: 0.0307 | Test Acc: 99.00%
Rank 0: Epoch 13/15 | Train Loss: 0.0079 | Test Loss: 0.0783 | Test Acc: 97.60%
Rank 0: Epoch 14/15 | Train Loss: 0.0068 | Test Loss: 0.0192 | Test Acc: 99.35%
Rank 0: Epoch 15/15 | Train Loss: 0.0058 | Test Loss: 0.0217 | Test Acc: 99.30%
Rank 0: Training for base_channels=16 took 633.03 seconds.
Rank 0: Model with base_channels=16 saved to checkpoints/double_descent/model_base_ch_16.pt

--- Rank 0: Training model with base_channels = 18 ---
Rank 0: Number of parameters: 221,806
Rank 0: Epoch 1/15 | Train Loss: 0.6054 | Test Loss: 0.1410 | Test Acc: 97.18%
Rank 0: Epoch 2/15 | Train Loss: 0.0693 | Test Loss: 0.1170 | Test Acc: 96.76%
Rank 0: Epoch 3/15 | Train Loss: 0.0418 | Test Loss: 0.0399 | Test Acc: 99.02%
Rank 0: Epoch 4/15 | Train Loss: 0.0320 | Test Loss: 0.0389 | Test Acc: 98.92%
Rank 0: Epoch 5/15 | Train Loss: 0.0235 | Test Loss: 0.0272 | Test Acc: 99.20%
Rank 0: Epoch 6/15 | Train Loss: 0.0202 | Test Loss: 0.0301 | Test Acc: 99.22%
Rank 0: Epoch 7/15 | Train Loss: 0.0171 | Test Loss: 0.0359 | Test Acc: 99.04%
Rank 0: Epoch 8/15 | Train Loss: 0.0148 | Test Loss: 0.0321 | Test Acc: 99.10%
Rank 0: Epoch 9/15 | Train Loss: 0.0125 | Test Loss: 0.0404 | Test Acc: 98.93%
Traceback (most recent call last):
  File "<string>", line 1, in <module>
  File "/lab/haoq_lab/cse12212635/.conda/envs/dl/lib/python3.11/multiprocessing/spawn.py", line 122, in spawn_main
    exitcode = _main(fd, parent_sentinel)
               ^^^^^^^^^^^^^^^^^^^^^^^^^^
  File "/lab/haoq_lab/cse12212635/.conda/envs/dl/lib/python3.11/multiprocessing/spawn.py", line 131, in _main
    prepare(preparation_data)
  File "/lab/haoq_lab/cse12212635/.conda/envs/dl/lib/python3.11/multiprocessing/spawn.py", line 246, in prepare
    _fixup_main_from_path(data['init_main_from_path'])
  File "/lab/haoq_lab/cse12212635/.conda/envs/dl/lib/python3.11/multiprocessing/spawn.py", line 297, in _fixup_main_from_path
    main_content = runpy.run_path(main_path,
                   ^^^^^^^^^^^^^^^^^^^^^^^^^
  File "<frozen runpy>", line 291, in run_path
  File "<frozen runpy>", line 98, in _run_module_code
  File "<frozen runpy>", line 88, in _run_code
  File "/lab/haoq_lab/cse12212635/slds_progect1/double_descent.py", line 16, in <module>
    from models.cnn import CNNBlock, CNNv4
  File "/lab/haoq_lab/cse12212635/slds_progect1/models/cnn.py", line 221
    
    ^
IndentationError: expected an indented block after class definition on line 220
Traceback (most recent call last):
  File "<string>", line 1, in <module>
  File "/lab/haoq_lab/cse12212635/.conda/envs/dl/lib/python3.11/multiprocessing/spawn.py", line 122, in spawn_main
    exitcode = _main(fd, parent_sentinel)
               ^^^^^^^^^^^^^^^^^^^^^^^^^^
  File "/lab/haoq_lab/cse12212635/.conda/envs/dl/lib/python3.11/multiprocessing/spawn.py", line 131, in _main
    prepare(preparation_data)
  File "/lab/haoq_lab/cse12212635/.conda/envs/dl/lib/python3.11/multiprocessing/spawn.py", line 246, in prepare
Traceback (most recent call last):
  File "<string>", line 1, in <module>
  File "/lab/haoq_lab/cse12212635/.conda/envs/dl/lib/python3.11/multiprocessing/spawn.py", line 122, in spawn_main
    _fixup_main_from_path(data['init_main_from_path'])
  File "/lab/haoq_lab/cse12212635/.conda/envs/dl/lib/python3.11/multiprocessing/spawn.py", line 297, in _fixup_main_from_path
    main_content = runpy.run_path(main_path,
                   ^^^^^^^^^^^^^^^^^^^^^^^^^
  File "<frozen runpy>", line 291, in run_path
  File "<frozen runpy>", line 98, in _run_module_code
  File "<frozen runpy>", line 88, in _run_code
  File "/lab/haoq_lab/cse12212635/slds_progect1/double_descent.py", line 16, in <module>
    exitcode = _main(fd, parent_sentinel)
               ^^^^^^^^^^^^^^^^^^^^^^^^^^
  File "/lab/haoq_lab/cse12212635/.conda/envs/dl/lib/python3.11/multiprocessing/spawn.py", line 131, in _main
    from models.cnn import CNNBlock, CNNv4
  File "/lab/haoq_lab/cse12212635/slds_progect1/models/cnn.py", line 221
    
    ^
IndentationError: expected an indented block after class definition on line 220
    prepare(preparation_data)
  File "/lab/haoq_lab/cse12212635/.conda/envs/dl/lib/python3.11/multiprocessing/spawn.py", line 246, in prepare
    _fixup_main_from_path(data['init_main_from_path'])
  File "/lab/haoq_lab/cse12212635/.conda/envs/dl/lib/python3.11/multiprocessing/spawn.py", line 297, in _fixup_main_from_path
Traceback (most recent call last):
  File "<string>", line 1, in <module>
  File "/lab/haoq_lab/cse12212635/.conda/envs/dl/lib/python3.11/multiprocessing/spawn.py", line 122, in spawn_main
    main_content = runpy.run_path(main_path,
    exitcode = _main(fd, parent_sentinel)
                   ^^^^^^^^^^^^^^^^^^^^^^^^^
  File "<frozen runpy>", line 291, in run_path
  File "<frozen runpy>", line 98, in _run_module_code
  File "<frozen runpy>", line 88, in _run_code
  File "/lab/haoq_lab/cse12212635/slds_progect1/double_descent.py", line 16, in <module>
               ^^^^^^^^^^^^^^^^^^^^^^^^^^
  File "/lab/haoq_lab/cse12212635/.conda/envs/dl/lib/python3.11/multiprocessing/spawn.py", line 131, in _main
    from models.cnn import CNNBlock, CNNv4
  File "/lab/haoq_lab/cse12212635/slds_progect1/models/cnn.py", line 221
    
    ^
IndentationError: expected an indented block after class definition on line 220
    prepare(preparation_data)
  File "/lab/haoq_lab/cse12212635/.conda/envs/dl/lib/python3.11/multiprocessing/spawn.py", line 246, in prepare
    _fixup_main_from_path(data['init_main_from_path'])
  File "/lab/haoq_lab/cse12212635/.conda/envs/dl/lib/python3.11/multiprocessing/spawn.py", line 297, in _fixup_main_from_path
    main_content = runpy.run_path(main_path,
                   ^^^^^^^^^^^^^^^^^^^^^^^^^
  File "<frozen runpy>", line 291, in run_path
  File "<frozen runpy>", line 98, in _run_module_code
  File "<frozen runpy>", line 88, in _run_code
  File "/lab/haoq_lab/cse12212635/slds_progect1/double_descent.py", line 16, in <module>
    from models.cnn import CNNBlock, CNNv4
  File "/lab/haoq_lab/cse12212635/slds_progect1/models/cnn.py", line 221
    
    ^
IndentationError: expected an indented block after class definition on line 220
Traceback (most recent call last):
  File "<string>", line 1, in <module>
  File "/lab/haoq_lab/cse12212635/.conda/envs/dl/lib/python3.11/multiprocessing/spawn.py", line 122, in spawn_main
    exitcode = _main(fd, parent_sentinel)
               ^^^^^^^^^^^^^^^^^^^^^^^^^^
  File "/lab/haoq_lab/cse12212635/.conda/envs/dl/lib/python3.11/multiprocessing/spawn.py", line 131, in _main
    prepare(preparation_data)
  File "/lab/haoq_lab/cse12212635/.conda/envs/dl/lib/python3.11/multiprocessing/spawn.py", line 246, in prepare
    _fixup_main_from_path(data['init_main_from_path'])
  File "/lab/haoq_lab/cse12212635/.conda/envs/dl/lib/python3.11/multiprocessing/spawn.py", line 297, in _fixup_main_from_path
    main_content = runpy.run_path(main_path,
                   ^^^^^^^^^^^^^^^^^^^^^^^^^
  File "<frozen runpy>", line 291, in run_path
  File "<frozen runpy>", line 98, in _run_module_code
  File "<frozen runpy>", line 88, in _run_code
  File "/lab/haoq_lab/cse12212635/slds_progect1/double_descent.py", line 16, in <module>
    from models.cnn import CNNBlock, CNNv4
  File "/lab/haoq_lab/cse12212635/slds_progect1/models/cnn.py", line 221
    
    ^
IndentationError: expected an indented block after class definition on line 220
Traceback (most recent call last):
  File "<string>", line 1, in <module>
  File "/lab/haoq_lab/cse12212635/.conda/envs/dl/lib/python3.11/multiprocessing/spawn.py", line 122, in spawn_main
    exitcode = _main(fd, parent_sentinel)
               ^^^^^^^^^^^^^^^^^^^^^^^^^^
  File "/lab/haoq_lab/cse12212635/.conda/envs/dl/lib/python3.11/multiprocessing/spawn.py", line 131, in _main
    prepare(preparation_data)
  File "/lab/haoq_lab/cse12212635/.conda/envs/dl/lib/python3.11/multiprocessing/spawn.py", line 246, in prepare
    _fixup_main_from_path(data['init_main_from_path'])
  File "/lab/haoq_lab/cse12212635/.conda/envs/dl/lib/python3.11/multiprocessing/spawn.py", line 297, in _fixup_main_from_path
    main_content = runpy.run_path(main_path,
                   ^^^^^^^^^^^^^^^^^^^^^^^^^
  File "<frozen runpy>", line 291, in run_path
  File "<frozen runpy>", line 98, in _run_module_code
  File "<frozen runpy>", line 88, in _run_code
  File "/lab/haoq_lab/cse12212635/slds_progect1/double_descent.py", line 16, in <module>
    from models.cnn import CNNBlock, CNNv4
  File "/lab/haoq_lab/cse12212635/slds_progect1/models/cnn.py", line 221
    
    ^
IndentationError: expected an indented block after class definition on line 220
Traceback (most recent call last):
  File "<string>", line 1, in <module>
  File "/lab/haoq_lab/cse12212635/.conda/envs/dl/lib/python3.11/multiprocessing/spawn.py", line 122, in spawn_main
    exitcode = _main(fd, parent_sentinel)
               ^^^^^^^^^^^^^^^^^^^^^^^^^^
  File "/lab/haoq_lab/cse12212635/.conda/envs/dl/lib/python3.11/multiprocessing/spawn.py", line 131, in _main
    prepare(preparation_data)
  File "/lab/haoq_lab/cse12212635/.conda/envs/dl/lib/python3.11/multiprocessing/spawn.py", line 246, in prepare
    _fixup_main_from_path(data['init_main_from_path'])
  File "/lab/haoq_lab/cse12212635/.conda/envs/dl/lib/python3.11/multiprocessing/spawn.py", line 297, in _fixup_main_from_path
    main_content = runpy.run_path(main_path,
                   ^^^^^^^^^^^^^^^^^^^^^^^^^
  File "<frozen runpy>", line 291, in run_path
  File "<frozen runpy>", line 98, in _run_module_code
  File "<frozen runpy>", line 88, in _run_code
  File "/lab/haoq_lab/cse12212635/slds_progect1/double_descent.py", line 16, in <module>
    from models.cnn import CNNBlock, CNNv4
  File "/lab/haoq_lab/cse12212635/slds_progect1/models/cnn.py", line 221
    
    ^
IndentationError: expected an indented block after class definition on line 220
Traceback (most recent call last):
  File "<string>", line 1, in <module>
  File "/lab/haoq_lab/cse12212635/.conda/envs/dl/lib/python3.11/multiprocessing/spawn.py", line 122, in spawn_main
    exitcode = _main(fd, parent_sentinel)
               ^^^^^^^^^^^^^^^^^^^^^^^^^^
  File "/lab/haoq_lab/cse12212635/.conda/envs/dl/lib/python3.11/multiprocessing/spawn.py", line 131, in _main
    prepare(preparation_data)
  File "/lab/haoq_lab/cse12212635/.conda/envs/dl/lib/python3.11/multiprocessing/spawn.py", line 246, in prepare
    _fixup_main_from_path(data['init_main_from_path'])
  File "/lab/haoq_lab/cse12212635/.conda/envs/dl/lib/python3.11/multiprocessing/spawn.py", line 297, in _fixup_main_from_path
    main_content = runpy.run_path(main_path,
                   ^^^^^^^^^^^^^^^^^^^^^^^^^
  File "<frozen runpy>", line 291, in run_path
  File "<frozen runpy>", line 98, in _run_module_code
  File "<frozen runpy>", line 88, in _run_code
  File "/lab/haoq_lab/cse12212635/slds_progect1/double_descent.py", line 16, in <module>
    from models.cnn import CNNBlock, CNNv4
  File "/lab/haoq_lab/cse12212635/slds_progect1/models/cnn.py", line 221
    
    ^
IndentationError: expected an indented block after class definition on line 220
Traceback (most recent call last):
  File "<string>", line 1, in <module>
  File "/lab/haoq_lab/cse12212635/.conda/envs/dl/lib/python3.11/multiprocessing/spawn.py", line 122, in spawn_main
    exitcode = _main(fd, parent_sentinel)
               ^^^^^^^^^^^^^^^^^^^^^^^^^^
  File "/lab/haoq_lab/cse12212635/.conda/envs/dl/lib/python3.11/multiprocessing/spawn.py", line 131, in _main
    prepare(preparation_data)
  File "/lab/haoq_lab/cse12212635/.conda/envs/dl/lib/python3.11/multiprocessing/spawn.py", line 246, in prepare
    _fixup_main_from_path(data['init_main_from_path'])
  File "/lab/haoq_lab/cse12212635/.conda/envs/dl/lib/python3.11/multiprocessing/spawn.py", line 297, in _fixup_main_from_path
    main_content = runpy.run_path(main_path,
                   ^^^^^^^^^^^^^^^^^^^^^^^^^
  File "<frozen runpy>", line 291, in run_path
  File "<frozen runpy>", line 98, in _run_module_code
  File "<frozen runpy>", line 88, in _run_code
  File "/lab/haoq_lab/cse12212635/slds_progect1/double_descent.py", line 16, in <module>
    from models.cnn import CNNBlock, CNNv4
  File "/lab/haoq_lab/cse12212635/slds_progect1/models/cnn.py", line 221
    
    ^
IndentationError: expected an indented block after class definition on line 220
Traceback (most recent call last):
  File "<string>", line 1, in <module>
  File "/lab/haoq_lab/cse12212635/.conda/envs/dl/lib/python3.11/multiprocessing/spawn.py", line 122, in spawn_main
    exitcode = _main(fd, parent_sentinel)
               ^^^^^^^^^^^^^^^^^^^^^^^^^^
  File "/lab/haoq_lab/cse12212635/.conda/envs/dl/lib/python3.11/multiprocessing/spawn.py", line 131, in _main
    prepare(preparation_data)
  File "/lab/haoq_lab/cse12212635/.conda/envs/dl/lib/python3.11/multiprocessing/spawn.py", line 246, in prepare
    _fixup_main_from_path(data['init_main_from_path'])
  File "/lab/haoq_lab/cse12212635/.conda/envs/dl/lib/python3.11/multiprocessing/spawn.py", line 297, in _fixup_main_from_path
    main_content = runpy.run_path(main_path,
                   ^^^^^^^^^^^^^^^^^^^^^^^^^
  File "<frozen runpy>", line 291, in run_path
  File "<frozen runpy>", line 98, in _run_module_code
  File "<frozen runpy>", line 88, in _run_code
  File "/lab/haoq_lab/cse12212635/slds_progect1/double_descent.py", line 16, in <module>
    from models.cnn import CNNBlock, CNNv4
  File "/lab/haoq_lab/cse12212635/slds_progect1/models/cnn.py", line 221
    
    ^
IndentationError: expected an indented block after class definition on line 220
Traceback (most recent call last):
  File "<string>", line 1, in <module>
  File "/lab/haoq_lab/cse12212635/.conda/envs/dl/lib/python3.11/multiprocessing/spawn.py", line 122, in spawn_main
Traceback (most recent call last):
  File "<string>", line 1, in <module>
  File "/lab/haoq_lab/cse12212635/.conda/envs/dl/lib/python3.11/multiprocessing/spawn.py", line 122, in spawn_main
Traceback (most recent call last):
  File "<string>", line 1, in <module>
  File "/lab/haoq_lab/cse12212635/.conda/envs/dl/lib/python3.11/multiprocessing/spawn.py", line 122, in spawn_main
    exitcode = _main(fd, parent_sentinel)
               ^^^^^^^^^^^^^^^^^^^^^^^^^^
  File "/lab/haoq_lab/cse12212635/.conda/envs/dl/lib/python3.11/multiprocessing/spawn.py", line 131, in _main
    exitcode = _main(fd, parent_sentinel)
               ^^^^^^^^^^^^^^^^^^^^^^^^^^
  File "/lab/haoq_lab/cse12212635/.conda/envs/dl/lib/python3.11/multiprocessing/spawn.py", line 131, in _main
    prepare(preparation_data)
  File "/lab/haoq_lab/cse12212635/.conda/envs/dl/lib/python3.11/multiprocessing/spawn.py", line 246, in prepare
    prepare(preparation_data)
  File "/lab/haoq_lab/cse12212635/.conda/envs/dl/lib/python3.11/multiprocessing/spawn.py", line 246, in prepare
    _fixup_main_from_path(data['init_main_from_path'])
  File "/lab/haoq_lab/cse12212635/.conda/envs/dl/lib/python3.11/multiprocessing/spawn.py", line 297, in _fixup_main_from_path
    _fixup_main_from_path(data['init_main_from_path'])
  File "/lab/haoq_lab/cse12212635/.conda/envs/dl/lib/python3.11/multiprocessing/spawn.py", line 297, in _fixup_main_from_path
    main_content = runpy.run_path(main_path,
                   ^^^^^^^^^^^^^^^^^^^^^^^^^
  File "<frozen runpy>", line 291, in run_path
  File "<frozen runpy>", line 98, in _run_module_code
  File "<frozen runpy>", line 88, in _run_code
  File "/lab/haoq_lab/cse12212635/slds_progect1/double_descent.py", line 16, in <module>
    main_content = runpy.run_path(main_path,
                   ^^^^^^^^^^^^^^^^^^^^^^^^^
  File "<frozen runpy>", line 291, in run_path
  File "<frozen runpy>", line 98, in _run_module_code
  File "<frozen runpy>", line 88, in _run_code
  File "/lab/haoq_lab/cse12212635/slds_progect1/double_descent.py", line 16, in <module>
    from models.cnn import CNNBlock, CNNv4
  File "/lab/haoq_lab/cse12212635/slds_progect1/models/cnn.py", line 221
    
    ^
IndentationError: expected an indented block after class definition on line 220
    exitcode = _main(fd, parent_sentinel)
               ^^^^^^^^^^^^^^^^^^^^^^^^^^
  File "/lab/haoq_lab/cse12212635/.conda/envs/dl/lib/python3.11/multiprocessing/spawn.py", line 131, in _main
    from models.cnn import CNNBlock, CNNv4
  File "/lab/haoq_lab/cse12212635/slds_progect1/models/cnn.py", line 221
    
    ^
IndentationError: expected an indented block after class definition on line 220
    prepare(preparation_data)
  File "/lab/haoq_lab/cse12212635/.conda/envs/dl/lib/python3.11/multiprocessing/spawn.py", line 246, in prepare
    _fixup_main_from_path(data['init_main_from_path'])
  File "/lab/haoq_lab/cse12212635/.conda/envs/dl/lib/python3.11/multiprocessing/spawn.py", line 297, in _fixup_main_from_path
    main_content = runpy.run_path(main_path,
                   ^^^^^^^^^^^^^^^^^^^^^^^^^
  File "<frozen runpy>", line 291, in run_path
  File "<frozen runpy>", line 98, in _run_module_code
  File "<frozen runpy>", line 88, in _run_code
  File "/lab/haoq_lab/cse12212635/slds_progect1/double_descent.py", line 16, in <module>
    from models.cnn import CNNBlock, CNNv4
  File "/lab/haoq_lab/cse12212635/slds_progect1/models/cnn.py", line 221
    
    ^
IndentationError: expected an indented block after class definition on line 220
Traceback (most recent call last):
  File "<string>", line 1, in <module>
  File "/lab/haoq_lab/cse12212635/.conda/envs/dl/lib/python3.11/multiprocessing/spawn.py", line 122, in spawn_main
    exitcode = _main(fd, parent_sentinel)
               ^^^^^^^^^^^^^^^^^^^^^^^^^^
  File "/lab/haoq_lab/cse12212635/.conda/envs/dl/lib/python3.11/multiprocessing/spawn.py", line 131, in _main
    prepare(preparation_data)
  File "/lab/haoq_lab/cse12212635/.conda/envs/dl/lib/python3.11/multiprocessing/spawn.py", line 246, in prepare
    _fixup_main_from_path(data['init_main_from_path'])
  File "/lab/haoq_lab/cse12212635/.conda/envs/dl/lib/python3.11/multiprocessing/spawn.py", line 297, in _fixup_main_from_path
    main_content = runpy.run_path(main_path,
                   ^^^^^^^^^^^^^^^^^^^^^^^^^
  File "<frozen runpy>", line 291, in run_path
  File "<frozen runpy>", line 98, in _run_module_code
  File "<frozen runpy>", line 88, in _run_code
  File "/lab/haoq_lab/cse12212635/slds_progect1/double_descent.py", line 16, in <module>
    from models.cnn import CNNBlock, CNNv4
  File "/lab/haoq_lab/cse12212635/slds_progect1/models/cnn.py", line 221
    
    ^
IndentationError: expected an indented block after class definition on line 220
Traceback (most recent call last):
  File "<string>", line 1, in <module>
  File "/lab/haoq_lab/cse12212635/.conda/envs/dl/lib/python3.11/multiprocessing/spawn.py", line 122, in spawn_main
    exitcode = _main(fd, parent_sentinel)
               ^^^^^^^^^^^^^^^^^^^^^^^^^^
  File "/lab/haoq_lab/cse12212635/.conda/envs/dl/lib/python3.11/multiprocessing/spawn.py", line 131, in _main
    prepare(preparation_data)
  File "/lab/haoq_lab/cse12212635/.conda/envs/dl/lib/python3.11/multiprocessing/spawn.py", line 246, in prepare
    _fixup_main_from_path(data['init_main_from_path'])
  File "/lab/haoq_lab/cse12212635/.conda/envs/dl/lib/python3.11/multiprocessing/spawn.py", line 297, in _fixup_main_from_path
    main_content = runpy.run_path(main_path,
                   ^^^^^^^^^^^^^^^^^^^^^^^^^
  File "<frozen runpy>", line 291, in run_path
  File "<frozen runpy>", line 98, in _run_module_code
  File "<frozen runpy>", line 88, in _run_code
  File "/lab/haoq_lab/cse12212635/slds_progect1/double_descent.py", line 16, in <module>
    from models.cnn import CNNBlock, CNNv4
  File "/lab/haoq_lab/cse12212635/slds_progect1/models/cnn.py", line 221
    
    ^
IndentationError: expected an indented block after class definition on line 220
Traceback (most recent call last):
  File "<string>", line 1, in <module>
  File "/lab/haoq_lab/cse12212635/.conda/envs/dl/lib/python3.11/multiprocessing/spawn.py", line 122, in spawn_main
    exitcode = _main(fd, parent_sentinel)
               ^^^^^^^^^^^^^^^^^^^^^^^^^^
  File "/lab/haoq_lab/cse12212635/.conda/envs/dl/lib/python3.11/multiprocessing/spawn.py", line 131, in _main
    prepare(preparation_data)
  File "/lab/haoq_lab/cse12212635/.conda/envs/dl/lib/python3.11/multiprocessing/spawn.py", line 246, in prepare
    _fixup_main_from_path(data['init_main_from_path'])
  File "/lab/haoq_lab/cse12212635/.conda/envs/dl/lib/python3.11/multiprocessing/spawn.py", line 297, in _fixup_main_from_path
    main_content = runpy.run_path(main_path,
                   ^^^^^^^^^^^^^^^^^^^^^^^^^
  File "<frozen runpy>", line 291, in run_path
  File "<frozen runpy>", line 98, in _run_module_code
  File "<frozen runpy>", line 88, in _run_code
  File "/lab/haoq_lab/cse12212635/slds_progect1/double_descent.py", line 16, in <module>
    from models.cnn import CNNBlock, CNNv4
  File "/lab/haoq_lab/cse12212635/slds_progect1/models/cnn.py", line 221
    
    ^
IndentationError: expected an indented block after class definition on line 220
Traceback (most recent call last):
  File "<string>", line 1, in <module>
  File "/lab/haoq_lab/cse12212635/.conda/envs/dl/lib/python3.11/multiprocessing/spawn.py", line 122, in spawn_main
    exitcode = _main(fd, parent_sentinel)
               ^^^^^^^^^^^^^^^^^^^^^^^^^^
  File "/lab/haoq_lab/cse12212635/.conda/envs/dl/lib/python3.11/multiprocessing/spawn.py", line 131, in _main
    prepare(preparation_data)
  File "/lab/haoq_lab/cse12212635/.conda/envs/dl/lib/python3.11/multiprocessing/spawn.py", line 246, in prepare
    _fixup_main_from_path(data['init_main_from_path'])
  File "/lab/haoq_lab/cse12212635/.conda/envs/dl/lib/python3.11/multiprocessing/spawn.py", line 297, in _fixup_main_from_path
    main_content = runpy.run_path(main_path,
                   ^^^^^^^^^^^^^^^^^^^^^^^^^
  File "<frozen runpy>", line 291, in run_path
  File "<frozen runpy>", line 98, in _run_module_code
  File "<frozen runpy>", line 88, in _run_code
  File "/lab/haoq_lab/cse12212635/slds_progect1/double_descent.py", line 16, in <module>
    from models.cnn import CNNBlock, CNNv4
  File "/lab/haoq_lab/cse12212635/slds_progect1/models/cnn.py", line 221
    
    ^
IndentationError: expected an indented block after class definition on line 220
Traceback (most recent call last):
  File "<string>", line 1, in <module>
  File "/lab/haoq_lab/cse12212635/.conda/envs/dl/lib/python3.11/multiprocessing/spawn.py", line 122, in spawn_main
Traceback (most recent call last):
  File "<string>", line 1, in <module>
  File "/lab/haoq_lab/cse12212635/.conda/envs/dl/lib/python3.11/multiprocessing/spawn.py", line 122, in spawn_main
Traceback (most recent call last):
  File "<string>", line 1, in <module>
  File "/lab/haoq_lab/cse12212635/.conda/envs/dl/lib/python3.11/multiprocessing/spawn.py", line 122, in spawn_main
    exitcode = _main(fd, parent_sentinel)
               ^^^^^^^^^^^^^^^^^^^^^^^^^^
  File "/lab/haoq_lab/cse12212635/.conda/envs/dl/lib/python3.11/multiprocessing/spawn.py", line 131, in _main
    exitcode = _main(fd, parent_sentinel)
               ^^^^^^^^^^^^^^^^^^^^^^^^^^
  File "/lab/haoq_lab/cse12212635/.conda/envs/dl/lib/python3.11/multiprocessing/spawn.py", line 131, in _main
    exitcode = _main(fd, parent_sentinel)
               ^^^^^^^^^^^^^^^^^^^^^^^^^^
  File "/lab/haoq_lab/cse12212635/.conda/envs/dl/lib/python3.11/multiprocessing/spawn.py", line 131, in _main
    prepare(preparation_data)
  File "/lab/haoq_lab/cse12212635/.conda/envs/dl/lib/python3.11/multiprocessing/spawn.py", line 246, in prepare
    prepare(preparation_data)
  File "/lab/haoq_lab/cse12212635/.conda/envs/dl/lib/python3.11/multiprocessing/spawn.py", line 246, in prepare
    _fixup_main_from_path(data['init_main_from_path'])
  File "/lab/haoq_lab/cse12212635/.conda/envs/dl/lib/python3.11/multiprocessing/spawn.py", line 297, in _fixup_main_from_path
    _fixup_main_from_path(data['init_main_from_path'])
  File "/lab/haoq_lab/cse12212635/.conda/envs/dl/lib/python3.11/multiprocessing/spawn.py", line 297, in _fixup_main_from_path
    main_content = runpy.run_path(main_path,
                   ^^^^^^^^^^^^^^^^^^^^^^^^^
  File "<frozen runpy>", line 291, in run_path
  File "<frozen runpy>", line 98, in _run_module_code
  File "<frozen runpy>", line 88, in _run_code
  File "/lab/haoq_lab/cse12212635/slds_progect1/double_descent.py", line 16, in <module>
    main_content = runpy.run_path(main_path,
                   ^^^^^^^^^^^^^^^^^^^^^^^^^
  File "<frozen runpy>", line 291, in run_path
  File "<frozen runpy>", line 98, in _run_module_code
  File "<frozen runpy>", line 88, in _run_code
  File "/lab/haoq_lab/cse12212635/slds_progect1/double_descent.py", line 16, in <module>
    prepare(preparation_data)
  File "/lab/haoq_lab/cse12212635/.conda/envs/dl/lib/python3.11/multiprocessing/spawn.py", line 246, in prepare
Traceback (most recent call last):
  File "<string>", line 1, in <module>
  File "/lab/haoq_lab/cse12212635/.conda/envs/dl/lib/python3.11/multiprocessing/spawn.py", line 122, in spawn_main
    _fixup_main_from_path(data['init_main_from_path'])
  File "/lab/haoq_lab/cse12212635/.conda/envs/dl/lib/python3.11/multiprocessing/spawn.py", line 297, in _fixup_main_from_path
    from models.cnn import CNNBlock, CNNv4
  File "/lab/haoq_lab/cse12212635/slds_progect1/models/cnn.py", line 221
    
    ^
IndentationError: expected an indented block after class definition on line 220
    from models.cnn import CNNBlock, CNNv4
  File "/lab/haoq_lab/cse12212635/slds_progect1/models/cnn.py", line 221
    
    ^
IndentationError: expected an indented block after class definition on line 220
    main_content = runpy.run_path(main_path,
                   ^^^^^^^^^^^^^^^^^^^^^^^^^
  File "<frozen runpy>", line 291, in run_path
  File "<frozen runpy>", line 98, in _run_module_code
  File "<frozen runpy>", line 88, in _run_code
  File "/lab/haoq_lab/cse12212635/slds_progect1/double_descent.py", line 16, in <module>
    exitcode = _main(fd, parent_sentinel)
               ^^^^^^^^^^^^^^^^^^^^^^^^^^
  File "/lab/haoq_lab/cse12212635/.conda/envs/dl/lib/python3.11/multiprocessing/spawn.py", line 131, in _main
    from models.cnn import CNNBlock, CNNv4
  File "/lab/haoq_lab/cse12212635/slds_progect1/models/cnn.py", line 221
    
    ^
IndentationError: expected an indented block after class definition on line 220
    prepare(preparation_data)
  File "/lab/haoq_lab/cse12212635/.conda/envs/dl/lib/python3.11/multiprocessing/spawn.py", line 246, in prepare
Traceback (most recent call last):
  File "<string>", line 1, in <module>
  File "/lab/haoq_lab/cse12212635/.conda/envs/dl/lib/python3.11/multiprocessing/spawn.py", line 122, in spawn_main
    exitcode = _main(fd, parent_sentinel)
               ^^^^^^^^^^^^^^^^^^^^^^^^^^
  File "/lab/haoq_lab/cse12212635/.conda/envs/dl/lib/python3.11/multiprocessing/spawn.py", line 131, in _main
    _fixup_main_from_path(data['init_main_from_path'])
  File "/lab/haoq_lab/cse12212635/.conda/envs/dl/lib/python3.11/multiprocessing/spawn.py", line 297, in _fixup_main_from_path
    prepare(preparation_data)
  File "/lab/haoq_lab/cse12212635/.conda/envs/dl/lib/python3.11/multiprocessing/spawn.py", line 246, in prepare
    main_content = runpy.run_path(main_path,
                   ^^^^^^^^^^^^^^^^^^^^^^^^^
  File "<frozen runpy>", line 291, in run_path
  File "<frozen runpy>", line 98, in _run_module_code
  File "<frozen runpy>", line 88, in _run_code
  File "/lab/haoq_lab/cse12212635/slds_progect1/double_descent.py", line 16, in <module>
    _fixup_main_from_path(data['init_main_from_path'])
  File "/lab/haoq_lab/cse12212635/.conda/envs/dl/lib/python3.11/multiprocessing/spawn.py", line 297, in _fixup_main_from_path
    from models.cnn import CNNBlock, CNNv4
  File "/lab/haoq_lab/cse12212635/slds_progect1/models/cnn.py", line 221
    
    ^
IndentationError: expected an indented block after class definition on line 220
    main_content = runpy.run_path(main_path,
                   ^^^^^^^^^^^^^^^^^^^^^^^^^
  File "<frozen runpy>", line 291, in run_path
  File "<frozen runpy>", line 98, in _run_module_code
  File "<frozen runpy>", line 88, in _run_code
  File "/lab/haoq_lab/cse12212635/slds_progect1/double_descent.py", line 16, in <module>
    from models.cnn import CNNBlock, CNNv4
  File "/lab/haoq_lab/cse12212635/slds_progect1/models/cnn.py", line 221
    
    ^
IndentationError: expected an indented block after class definition on line 220
Traceback (most recent call last):
  File "<string>", line 1, in <module>
  File "/lab/haoq_lab/cse12212635/.conda/envs/dl/lib/python3.11/multiprocessing/spawn.py", line 122, in spawn_main
    exitcode = _main(fd, parent_sentinel)
               ^^^^^^^^^^^^^^^^^^^^^^^^^^
  File "/lab/haoq_lab/cse12212635/.conda/envs/dl/lib/python3.11/multiprocessing/spawn.py", line 131, in _main
    prepare(preparation_data)
  File "/lab/haoq_lab/cse12212635/.conda/envs/dl/lib/python3.11/multiprocessing/spawn.py", line 246, in prepare
Traceback (most recent call last):
  File "<string>", line 1, in <module>
  File "/lab/haoq_lab/cse12212635/.conda/envs/dl/lib/python3.11/multiprocessing/spawn.py", line 122, in spawn_main
    _fixup_main_from_path(data['init_main_from_path'])
  File "/lab/haoq_lab/cse12212635/.conda/envs/dl/lib/python3.11/multiprocessing/spawn.py", line 297, in _fixup_main_from_path
    exitcode = _main(fd, parent_sentinel)
               ^^^^^^^^^^^^^^^^^^^^^^^^^^
  File "/lab/haoq_lab/cse12212635/.conda/envs/dl/lib/python3.11/multiprocessing/spawn.py", line 131, in _main
    prepare(preparation_data)
  File "/lab/haoq_lab/cse12212635/.conda/envs/dl/lib/python3.11/multiprocessing/spawn.py", line 246, in prepare
    _fixup_main_from_path(data['init_main_from_path'])
  File "/lab/haoq_lab/cse12212635/.conda/envs/dl/lib/python3.11/multiprocessing/spawn.py", line 297, in _fixup_main_from_path
    main_content = runpy.run_path(main_path,
                   ^^^^^^^^^^^^^^^^^^^^^^^^^
  File "<frozen runpy>", line 291, in run_path
  File "<frozen runpy>", line 98, in _run_module_code
  File "<frozen runpy>", line 88, in _run_code
  File "/lab/haoq_lab/cse12212635/slds_progect1/double_descent.py", line 16, in <module>
    main_content = runpy.run_path(main_path,
                   ^^^^^^^^^^^^^^^^^^^^^^^^^
  File "<frozen runpy>", line 291, in run_path
  File "<frozen runpy>", line 98, in _run_module_code
  File "<frozen runpy>", line 88, in _run_code
  File "/lab/haoq_lab/cse12212635/slds_progect1/double_descent.py", line 16, in <module>
    from models.cnn import CNNBlock, CNNv4
  File "/lab/haoq_lab/cse12212635/slds_progect1/models/cnn.py", line 221
    
    ^
IndentationError: expected an indented block after class definition on line 220
    from models.cnn import CNNBlock, CNNv4
  File "/lab/haoq_lab/cse12212635/slds_progect1/models/cnn.py", line 221
    
    ^
IndentationError: expected an indented block after class definition on line 220
Traceback (most recent call last):
  File "<string>", line 1, in <module>
  File "/lab/haoq_lab/cse12212635/.conda/envs/dl/lib/python3.11/multiprocessing/spawn.py", line 122, in spawn_main
    exitcode = _main(fd, parent_sentinel)
               ^^^^^^^^^^^^^^^^^^^^^^^^^^
  File "/lab/haoq_lab/cse12212635/.conda/envs/dl/lib/python3.11/multiprocessing/spawn.py", line 131, in _main
    prepare(preparation_data)
  File "/lab/haoq_lab/cse12212635/.conda/envs/dl/lib/python3.11/multiprocessing/spawn.py", line 246, in prepare
    _fixup_main_from_path(data['init_main_from_path'])
  File "/lab/haoq_lab/cse12212635/.conda/envs/dl/lib/python3.11/multiprocessing/spawn.py", line 297, in _fixup_main_from_path
    main_content = runpy.run_path(main_path,
                   ^^^^^^^^^^^^^^^^^^^^^^^^^
  File "<frozen runpy>", line 291, in run_path
  File "<frozen runpy>", line 98, in _run_module_code
  File "<frozen runpy>", line 88, in _run_code
  File "/lab/haoq_lab/cse12212635/slds_progect1/double_descent.py", line 16, in <module>
    from models.cnn import CNNBlock, CNNv4
  File "/lab/haoq_lab/cse12212635/slds_progect1/models/cnn.py", line 221
    
    ^
IndentationError: expected an indented block after class definition on line 220
Traceback (most recent call last):
Traceback (most recent call last):
  File "<string>", line 1, in <module>
  File "<string>", line 1, in <module>
  File "/lab/haoq_lab/cse12212635/.conda/envs/dl/lib/python3.11/multiprocessing/spawn.py", line 122, in spawn_main
  File "/lab/haoq_lab/cse12212635/.conda/envs/dl/lib/python3.11/multiprocessing/spawn.py", line 122, in spawn_main
    exitcode = _main(fd, parent_sentinel)
               ^^^^^^^^^^^^^^^^^^^^^^^^^^
  File "/lab/haoq_lab/cse12212635/.conda/envs/dl/lib/python3.11/multiprocessing/spawn.py", line 131, in _main
Traceback (most recent call last):
  File "<string>", line 1, in <module>
  File "/lab/haoq_lab/cse12212635/.conda/envs/dl/lib/python3.11/multiprocessing/spawn.py", line 122, in spawn_main
    prepare(preparation_data)
  File "/lab/haoq_lab/cse12212635/.conda/envs/dl/lib/python3.11/multiprocessing/spawn.py", line 246, in prepare
    exitcode = _main(fd, parent_sentinel)
               ^^^^^^^^^^^^^^^^^^^^^^^^^^
  File "/lab/haoq_lab/cse12212635/.conda/envs/dl/lib/python3.11/multiprocessing/spawn.py", line 131, in _main
    _fixup_main_from_path(data['init_main_from_path'])
  File "/lab/haoq_lab/cse12212635/.conda/envs/dl/lib/python3.11/multiprocessing/spawn.py", line 297, in _fixup_main_from_path
    prepare(preparation_data)
  File "/lab/haoq_lab/cse12212635/.conda/envs/dl/lib/python3.11/multiprocessing/spawn.py", line 246, in prepare
    main_content = runpy.run_path(main_path,
                   ^^^^^^^^^^^^^^^^^^^^^^^^^
  File "<frozen runpy>", line 291, in run_path
  File "<frozen runpy>", line 98, in _run_module_code
  File "<frozen runpy>", line 88, in _run_code
  File "/lab/haoq_lab/cse12212635/slds_progect1/double_descent.py", line 16, in <module>
    _fixup_main_from_path(data['init_main_from_path'])
  File "/lab/haoq_lab/cse12212635/.conda/envs/dl/lib/python3.11/multiprocessing/spawn.py", line 297, in _fixup_main_from_path
    main_content = runpy.run_path(main_path,
                   ^^^^^^^^^^^^^^^^^^^^^^^^^
  File "<frozen runpy>", line 291, in run_path
  File "<frozen runpy>", line 98, in _run_module_code
  File "<frozen runpy>", line 88, in _run_code
  File "/lab/haoq_lab/cse12212635/slds_progect1/double_descent.py", line 16, in <module>
    from models.cnn import CNNBlock, CNNv4
  File "/lab/haoq_lab/cse12212635/slds_progect1/models/cnn.py", line 221
    
    ^
IndentationError: expected an indented block after class definition on line 220
    from models.cnn import CNNBlock, CNNv4
  File "/lab/haoq_lab/cse12212635/slds_progect1/models/cnn.py", line 221
    
    ^
IndentationError: expected an indented block after class definition on line 220
    exitcode = _main(fd, parent_sentinel)
               ^^^^^^^^^^^^^^^^^^^^^^^^^^
  File "/lab/haoq_lab/cse12212635/.conda/envs/dl/lib/python3.11/multiprocessing/spawn.py", line 131, in _main
    prepare(preparation_data)
  File "/lab/haoq_lab/cse12212635/.conda/envs/dl/lib/python3.11/multiprocessing/spawn.py", line 246, in prepare
    _fixup_main_from_path(data['init_main_from_path'])
  File "/lab/haoq_lab/cse12212635/.conda/envs/dl/lib/python3.11/multiprocessing/spawn.py", line 297, in _fixup_main_from_path
    main_content = runpy.run_path(main_path,
                   ^^^^^^^^^^^^^^^^^^^^^^^^^
  File "<frozen runpy>", line 291, in run_path
  File "<frozen runpy>", line 98, in _run_module_code
  File "<frozen runpy>", line 88, in _run_code
  File "/lab/haoq_lab/cse12212635/slds_progect1/double_descent.py", line 16, in <module>
    from models.cnn import CNNBlock, CNNv4
  File "/lab/haoq_lab/cse12212635/slds_progect1/models/cnn.py", line 221
    
    ^
IndentationError: expected an indented block after class definition on line 220
Traceback (most recent call last):
  File "<string>", line 1, in <module>
  File "/lab/haoq_lab/cse12212635/.conda/envs/dl/lib/python3.11/multiprocessing/spawn.py", line 122, in spawn_main
    exitcode = _main(fd, parent_sentinel)
               ^^^^^^^^^^^^^^^^^^^^^^^^^^
  File "/lab/haoq_lab/cse12212635/.conda/envs/dl/lib/python3.11/multiprocessing/spawn.py", line 131, in _main
    prepare(preparation_data)
  File "/lab/haoq_lab/cse12212635/.conda/envs/dl/lib/python3.11/multiprocessing/spawn.py", line 246, in prepare
    _fixup_main_from_path(data['init_main_from_path'])
  File "/lab/haoq_lab/cse12212635/.conda/envs/dl/lib/python3.11/multiprocessing/spawn.py", line 297, in _fixup_main_from_path
    main_content = runpy.run_path(main_path,
                   ^^^^^^^^^^^^^^^^^^^^^^^^^
  File "<frozen runpy>", line 291, in run_path
  File "<frozen runpy>", line 98, in _run_module_code
  File "<frozen runpy>", line 88, in _run_code
  File "/lab/haoq_lab/cse12212635/slds_progect1/double_descent.py", line 16, in <module>
    from models.cnn import CNNBlock, CNNv4
  File "/lab/haoq_lab/cse12212635/slds_progect1/models/cnn.py", line 221
    
    ^
IndentationError: expected an indented block after class definition on line 220
Traceback (most recent call last):
  File "<string>", line 1, in <module>
  File "/lab/haoq_lab/cse12212635/.conda/envs/dl/lib/python3.11/multiprocessing/spawn.py", line 122, in spawn_main
    exitcode = _main(fd, parent_sentinel)
               ^^^^^^^^^^^^^^^^^^^^^^^^^^
  File "/lab/haoq_lab/cse12212635/.conda/envs/dl/lib/python3.11/multiprocessing/spawn.py", line 131, in _main
    prepare(preparation_data)
  File "/lab/haoq_lab/cse12212635/.conda/envs/dl/lib/python3.11/multiprocessing/spawn.py", line 246, in prepare
    _fixup_main_from_path(data['init_main_from_path'])
  File "/lab/haoq_lab/cse12212635/.conda/envs/dl/lib/python3.11/multiprocessing/spawn.py", line 297, in _fixup_main_from_path
    main_content = runpy.run_path(main_path,
                   ^^^^^^^^^^^^^^^^^^^^^^^^^
  File "<frozen runpy>", line 291, in run_path
  File "<frozen runpy>", line 98, in _run_module_code
  File "<frozen runpy>", line 88, in _run_code
  File "/lab/haoq_lab/cse12212635/slds_progect1/double_descent.py", line 16, in <module>
    from models.cnn import CNNBlock, CNNv4
  File "/lab/haoq_lab/cse12212635/slds_progect1/models/cnn.py", line 221
    
    ^
IndentationError: expected an indented block after class definition on line 220
Traceback (most recent call last):
  File "<string>", line 1, in <module>
  File "/lab/haoq_lab/cse12212635/.conda/envs/dl/lib/python3.11/multiprocessing/spawn.py", line 122, in spawn_main
    exitcode = _main(fd, parent_sentinel)
               ^^^^^^^^^^^^^^^^^^^^^^^^^^
  File "/lab/haoq_lab/cse12212635/.conda/envs/dl/lib/python3.11/multiprocessing/spawn.py", line 131, in _main
    prepare(preparation_data)
  File "/lab/haoq_lab/cse12212635/.conda/envs/dl/lib/python3.11/multiprocessing/spawn.py", line 246, in prepare
    _fixup_main_from_path(data['init_main_from_path'])
  File "/lab/haoq_lab/cse12212635/.conda/envs/dl/lib/python3.11/multiprocessing/spawn.py", line 297, in _fixup_main_from_path
    main_content = runpy.run_path(main_path,
                   ^^^^^^^^^^^^^^^^^^^^^^^^^
  File "<frozen runpy>", line 291, in run_path
  File "<frozen runpy>", line 98, in _run_module_code
  File "<frozen runpy>", line 88, in _run_code
  File "/lab/haoq_lab/cse12212635/slds_progect1/double_descent.py", line 16, in <module>
    from models.cnn import CNNBlock, CNNv4
  File "/lab/haoq_lab/cse12212635/slds_progect1/models/cnn.py", line 221
    
    ^
IndentationError: expected an indented block after class definition on line 220
Traceback (most recent call last):
  File "<string>", line 1, in <module>
  File "/lab/haoq_lab/cse12212635/.conda/envs/dl/lib/python3.11/multiprocessing/spawn.py", line 122, in spawn_main
    exitcode = _main(fd, parent_sentinel)
               ^^^^^^^^^^^^^^^^^^^^^^^^^^
  File "/lab/haoq_lab/cse12212635/.conda/envs/dl/lib/python3.11/multiprocessing/spawn.py", line 131, in _main
Traceback (most recent call last):
  File "<string>", line 1, in <module>
  File "/lab/haoq_lab/cse12212635/.conda/envs/dl/lib/python3.11/multiprocessing/spawn.py", line 122, in spawn_main
    prepare(preparation_data)
  File "/lab/haoq_lab/cse12212635/.conda/envs/dl/lib/python3.11/multiprocessing/spawn.py", line 246, in prepare
    _fixup_main_from_path(data['init_main_from_path'])
  File "/lab/haoq_lab/cse12212635/.conda/envs/dl/lib/python3.11/multiprocessing/spawn.py", line 297, in _fixup_main_from_path
    main_content = runpy.run_path(main_path,
                   ^^^^^^^^^^^^^^^^^^^^^^^^^
  File "<frozen runpy>", line 291, in run_path
  File "<frozen runpy>", line 98, in _run_module_code
  File "<frozen runpy>", line 88, in _run_code
  File "/lab/haoq_lab/cse12212635/slds_progect1/double_descent.py", line 16, in <module>
    from models.cnn import CNNBlock, CNNv4
  File "/lab/haoq_lab/cse12212635/slds_progect1/models/cnn.py", line 221
    
    ^
IndentationError: expected an indented block after class definition on line 220
    exitcode = _main(fd, parent_sentinel)
               ^^^^^^^^^^^^^^^^^^^^^^^^^^
  File "/lab/haoq_lab/cse12212635/.conda/envs/dl/lib/python3.11/multiprocessing/spawn.py", line 131, in _main
    prepare(preparation_data)
  File "/lab/haoq_lab/cse12212635/.conda/envs/dl/lib/python3.11/multiprocessing/spawn.py", line 246, in prepare
    _fixup_main_from_path(data['init_main_from_path'])
  File "/lab/haoq_lab/cse12212635/.conda/envs/dl/lib/python3.11/multiprocessing/spawn.py", line 297, in _fixup_main_from_path
    main_content = runpy.run_path(main_path,
                   ^^^^^^^^^^^^^^^^^^^^^^^^^
  File "<frozen runpy>", line 291, in run_path
  File "<frozen runpy>", line 98, in _run_module_code
  File "<frozen runpy>", line 88, in _run_code
  File "/lab/haoq_lab/cse12212635/slds_progect1/double_descent.py", line 16, in <module>
    from models.cnn import CNNBlock, CNNv4
  File "/lab/haoq_lab/cse12212635/slds_progect1/models/cnn.py", line 221
    
    ^
IndentationError: expected an indented block after class definition on line 220
Traceback (most recent call last):
  File "<string>", line 1, in <module>
  File "/lab/haoq_lab/cse12212635/.conda/envs/dl/lib/python3.11/multiprocessing/spawn.py", line 122, in spawn_main
Traceback (most recent call last):
  File "<string>", line 1, in <module>
  File "/lab/haoq_lab/cse12212635/.conda/envs/dl/lib/python3.11/multiprocessing/spawn.py", line 122, in spawn_main
Traceback (most recent call last):
  File "<string>", line 1, in <module>
  File "/lab/haoq_lab/cse12212635/.conda/envs/dl/lib/python3.11/multiprocessing/spawn.py", line 122, in spawn_main
Traceback (most recent call last):
  File "<string>", line 1, in <module>
  File "/lab/haoq_lab/cse12212635/.conda/envs/dl/lib/python3.11/multiprocessing/spawn.py", line 122, in spawn_main
    exitcode = _main(fd, parent_sentinel)
               ^^^^^^^^^^^^^^^^^^^^^^^^^^
  File "/lab/haoq_lab/cse12212635/.conda/envs/dl/lib/python3.11/multiprocessing/spawn.py", line 131, in _main
    exitcode = _main(fd, parent_sentinel)
               ^^^^^^^^^^^^^^^^^^^^^^^^^^
  File "/lab/haoq_lab/cse12212635/.conda/envs/dl/lib/python3.11/multiprocessing/spawn.py", line 131, in _main
    prepare(preparation_data)
  File "/lab/haoq_lab/cse12212635/.conda/envs/dl/lib/python3.11/multiprocessing/spawn.py", line 246, in prepare
    prepare(preparation_data)
  File "/lab/haoq_lab/cse12212635/.conda/envs/dl/lib/python3.11/multiprocessing/spawn.py", line 246, in prepare
    _fixup_main_from_path(data['init_main_from_path'])
  File "/lab/haoq_lab/cse12212635/.conda/envs/dl/lib/python3.11/multiprocessing/spawn.py", line 297, in _fixup_main_from_path
    _fixup_main_from_path(data['init_main_from_path'])
  File "/lab/haoq_lab/cse12212635/.conda/envs/dl/lib/python3.11/multiprocessing/spawn.py", line 297, in _fixup_main_from_path
    main_content = runpy.run_path(main_path,
                   ^^^^^^^^^^^^^^^^^^^^^^^^^
  File "<frozen runpy>", line 291, in run_path
  File "<frozen runpy>", line 98, in _run_module_code
  File "<frozen runpy>", line 88, in _run_code
  File "/lab/haoq_lab/cse12212635/slds_progect1/double_descent.py", line 16, in <module>
    main_content = runpy.run_path(main_path,
                   ^^^^^^^^^^^^^^^^^^^^^^^^^
  File "<frozen runpy>", line 291, in run_path
  File "<frozen runpy>", line 98, in _run_module_code
  File "<frozen runpy>", line 88, in _run_code
  File "/lab/haoq_lab/cse12212635/slds_progect1/double_descent.py", line 16, in <module>
    exitcode = _main(fd, parent_sentinel)
               ^^^^^^^^^^^^^^^^^^^^^^^^^^
  File "/lab/haoq_lab/cse12212635/.conda/envs/dl/lib/python3.11/multiprocessing/spawn.py", line 131, in _main
    exitcode = _main(fd, parent_sentinel)
               ^^^^^^^^^^^^^^^^^^^^^^^^^^
  File "/lab/haoq_lab/cse12212635/.conda/envs/dl/lib/python3.11/multiprocessing/spawn.py", line 131, in _main
    prepare(preparation_data)
  File "/lab/haoq_lab/cse12212635/.conda/envs/dl/lib/python3.11/multiprocessing/spawn.py", line 246, in prepare
    _fixup_main_from_path(data['init_main_from_path'])
  File "/lab/haoq_lab/cse12212635/.conda/envs/dl/lib/python3.11/multiprocessing/spawn.py", line 297, in _fixup_main_from_path
    main_content = runpy.run_path(main_path,
                   ^^^^^^^^^^^^^^^^^^^^^^^^^
  File "<frozen runpy>", line 291, in run_path
  File "<frozen runpy>", line 98, in _run_module_code
  File "<frozen runpy>", line 88, in _run_code
  File "/lab/haoq_lab/cse12212635/slds_progect1/double_descent.py", line 16, in <module>
    prepare(preparation_data)
  File "/lab/haoq_lab/cse12212635/.conda/envs/dl/lib/python3.11/multiprocessing/spawn.py", line 246, in prepare
    from models.cnn import CNNBlock, CNNv4
  File "/lab/haoq_lab/cse12212635/slds_progect1/models/cnn.py", line 221
    
    ^
IndentationError: expected an indented block after class definition on line 220
    from models.cnn import CNNBlock, CNNv4
  File "/lab/haoq_lab/cse12212635/slds_progect1/models/cnn.py", line 221
    
    ^
IndentationError: expected an indented block after class definition on line 220
    from models.cnn import CNNBlock, CNNv4
  File "/lab/haoq_lab/cse12212635/slds_progect1/models/cnn.py", line 221
    
    ^
IndentationError: expected an indented block after class definition on line 220
    _fixup_main_from_path(data['init_main_from_path'])
  File "/lab/haoq_lab/cse12212635/.conda/envs/dl/lib/python3.11/multiprocessing/spawn.py", line 297, in _fixup_main_from_path
    main_content = runpy.run_path(main_path,
                   ^^^^^^^^^^^^^^^^^^^^^^^^^
  File "<frozen runpy>", line 291, in run_path
  File "<frozen runpy>", line 98, in _run_module_code
  File "<frozen runpy>", line 88, in _run_code
  File "/lab/haoq_lab/cse12212635/slds_progect1/double_descent.py", line 16, in <module>
    from models.cnn import CNNBlock, CNNv4
  File "/lab/haoq_lab/cse12212635/slds_progect1/models/cnn.py", line 221
    
    ^
IndentationError: expected an indented block after class definition on line 220
Traceback (most recent call last):
  File "<string>", line 1, in <module>
  File "/lab/haoq_lab/cse12212635/.conda/envs/dl/lib/python3.11/multiprocessing/spawn.py", line 122, in spawn_main
    exitcode = _main(fd, parent_sentinel)
               ^^^^^^^^^^^^^^^^^^^^^^^^^^
  File "/lab/haoq_lab/cse12212635/.conda/envs/dl/lib/python3.11/multiprocessing/spawn.py", line 131, in _main
    prepare(preparation_data)
  File "/lab/haoq_lab/cse12212635/.conda/envs/dl/lib/python3.11/multiprocessing/spawn.py", line 246, in prepare
    _fixup_main_from_path(data['init_main_from_path'])
  File "/lab/haoq_lab/cse12212635/.conda/envs/dl/lib/python3.11/multiprocessing/spawn.py", line 297, in _fixup_main_from_path
    main_content = runpy.run_path(main_path,
                   ^^^^^^^^^^^^^^^^^^^^^^^^^
  File "<frozen runpy>", line 291, in run_path
  File "<frozen runpy>", line 98, in _run_module_code
  File "<frozen runpy>", line 88, in _run_code
  File "/lab/haoq_lab/cse12212635/slds_progect1/double_descent.py", line 16, in <module>
    from models.cnn import CNNBlock, CNNv4
  File "/lab/haoq_lab/cse12212635/slds_progect1/models/cnn.py", line 221
    
    ^
IndentationError: expected an indented block after class definition on line 220
Traceback (most recent call last):
  File "<string>", line 1, in <module>
  File "/lab/haoq_lab/cse12212635/.conda/envs/dl/lib/python3.11/multiprocessing/spawn.py", line 122, in spawn_main
    exitcode = _main(fd, parent_sentinel)
               ^^^^^^^^^^^^^^^^^^^^^^^^^^
  File "/lab/haoq_lab/cse12212635/.conda/envs/dl/lib/python3.11/multiprocessing/spawn.py", line 131, in _main
    prepare(preparation_data)
  File "/lab/haoq_lab/cse12212635/.conda/envs/dl/lib/python3.11/multiprocessing/spawn.py", line 246, in prepare
    _fixup_main_from_path(data['init_main_from_path'])
  File "/lab/haoq_lab/cse12212635/.conda/envs/dl/lib/python3.11/multiprocessing/spawn.py", line 297, in _fixup_main_from_path
    main_content = runpy.run_path(main_path,
                   ^^^^^^^^^^^^^^^^^^^^^^^^^
  File "<frozen runpy>", line 291, in run_path
  File "<frozen runpy>", line 98, in _run_module_code
  File "<frozen runpy>", line 88, in _run_code
  File "/lab/haoq_lab/cse12212635/slds_progect1/double_descent.py", line 16, in <module>
    from models.cnn import CNNBlock, CNNv4
  File "/lab/haoq_lab/cse12212635/slds_progect1/models/cnn.py", line 221
    
    ^
IndentationError: expected an indented block after class definition on line 220
Traceback (most recent call last):
  File "<string>", line 1, in <module>
  File "/lab/haoq_lab/cse12212635/.conda/envs/dl/lib/python3.11/multiprocessing/spawn.py", line 122, in spawn_main
    exitcode = _main(fd, parent_sentinel)
               ^^^^^^^^^^^^^^^^^^^^^^^^^^
  File "/lab/haoq_lab/cse12212635/.conda/envs/dl/lib/python3.11/multiprocessing/spawn.py", line 131, in _main
    prepare(preparation_data)
  File "/lab/haoq_lab/cse12212635/.conda/envs/dl/lib/python3.11/multiprocessing/spawn.py", line 246, in prepare
    _fixup_main_from_path(data['init_main_from_path'])
  File "/lab/haoq_lab/cse12212635/.conda/envs/dl/lib/python3.11/multiprocessing/spawn.py", line 297, in _fixup_main_from_path
    main_content = runpy.run_path(main_path,
                   ^^^^^^^^^^^^^^^^^^^^^^^^^
  File "<frozen runpy>", line 291, in run_path
  File "<frozen runpy>", line 98, in _run_module_code
  File "<frozen runpy>", line 88, in _run_code
  File "/lab/haoq_lab/cse12212635/slds_progect1/double_descent.py", line 16, in <module>
    from models.cnn import CNNBlock, CNNv4
  File "/lab/haoq_lab/cse12212635/slds_progect1/models/cnn.py", line 221
    
    ^
IndentationError: expected an indented block after class definition on line 220
Traceback (most recent call last):
  File "<string>", line 1, in <module>
  File "/lab/haoq_lab/cse12212635/.conda/envs/dl/lib/python3.11/multiprocessing/spawn.py", line 122, in spawn_main
    exitcode = _main(fd, parent_sentinel)
               ^^^^^^^^^^^^^^^^^^^^^^^^^^
  File "/lab/haoq_lab/cse12212635/.conda/envs/dl/lib/python3.11/multiprocessing/spawn.py", line 131, in _main
    prepare(preparation_data)
  File "/lab/haoq_lab/cse12212635/.conda/envs/dl/lib/python3.11/multiprocessing/spawn.py", line 246, in prepare
    _fixup_main_from_path(data['init_main_from_path'])
  File "/lab/haoq_lab/cse12212635/.conda/envs/dl/lib/python3.11/multiprocessing/spawn.py", line 297, in _fixup_main_from_path
    main_content = runpy.run_path(main_path,
                   ^^^^^^^^^^^^^^^^^^^^^^^^^
  File "<frozen runpy>", line 291, in run_path
  File "<frozen runpy>", line 98, in _run_module_code
  File "<frozen runpy>", line 88, in _run_code
  File "/lab/haoq_lab/cse12212635/slds_progect1/double_descent.py", line 16, in <module>
    from models.cnn import CNNBlock, CNNv4
  File "/lab/haoq_lab/cse12212635/slds_progect1/models/cnn.py", line 221
    
    ^
IndentationError: expected an indented block after class definition on line 220
Traceback (most recent call last):
  File "<string>", line 1, in <module>
  File "/lab/haoq_lab/cse12212635/.conda/envs/dl/lib/python3.11/multiprocessing/spawn.py", line 122, in spawn_main
    exitcode = _main(fd, parent_sentinel)
               ^^^^^^^^^^^^^^^^^^^^^^^^^^
  File "/lab/haoq_lab/cse12212635/.conda/envs/dl/lib/python3.11/multiprocessing/spawn.py", line 131, in _main
    prepare(preparation_data)
  File "/lab/haoq_lab/cse12212635/.conda/envs/dl/lib/python3.11/multiprocessing/spawn.py", line 246, in prepare
    _fixup_main_from_path(data['init_main_from_path'])
  File "/lab/haoq_lab/cse12212635/.conda/envs/dl/lib/python3.11/multiprocessing/spawn.py", line 297, in _fixup_main_from_path
    main_content = runpy.run_path(main_path,
                   ^^^^^^^^^^^^^^^^^^^^^^^^^
  File "<frozen runpy>", line 291, in run_path
  File "<frozen runpy>", line 98, in _run_module_code
  File "<frozen runpy>", line 88, in _run_code
  File "/lab/haoq_lab/cse12212635/slds_progect1/double_descent.py", line 16, in <module>
    from models.cnn import CNNBlock, CNNv4
  File "/lab/haoq_lab/cse12212635/slds_progect1/models/cnn.py", line 221
    
    ^
IndentationError: expected an indented block after class definition on line 220
Traceback (most recent call last):
  File "<string>", line 1, in <module>
  File "/lab/haoq_lab/cse12212635/.conda/envs/dl/lib/python3.11/multiprocessing/spawn.py", line 122, in spawn_main
    exitcode = _main(fd, parent_sentinel)
               ^^^^^^^^^^^^^^^^^^^^^^^^^^
  File "/lab/haoq_lab/cse12212635/.conda/envs/dl/lib/python3.11/multiprocessing/spawn.py", line 131, in _main
    prepare(preparation_data)
  File "/lab/haoq_lab/cse12212635/.conda/envs/dl/lib/python3.11/multiprocessing/spawn.py", line 246, in prepare
    _fixup_main_from_path(data['init_main_from_path'])
  File "/lab/haoq_lab/cse12212635/.conda/envs/dl/lib/python3.11/multiprocessing/spawn.py", line 297, in _fixup_main_from_path
    main_content = runpy.run_path(main_path,
                   ^^^^^^^^^^^^^^^^^^^^^^^^^
  File "<frozen runpy>", line 291, in run_path
  File "<frozen runpy>", line 98, in _run_module_code
  File "<frozen runpy>", line 88, in _run_code
  File "/lab/haoq_lab/cse12212635/slds_progect1/double_descent.py", line 16, in <module>
    from models.cnn import CNNBlock, CNNv4
  File "/lab/haoq_lab/cse12212635/slds_progect1/models/cnn.py", line 221
    
    ^
IndentationError: expected an indented block after class definition on line 220
Traceback (most recent call last):
  File "<string>", line 1, in <module>
  File "/lab/haoq_lab/cse12212635/.conda/envs/dl/lib/python3.11/multiprocessing/spawn.py", line 122, in spawn_main
    exitcode = _main(fd, parent_sentinel)
               ^^^^^^^^^^^^^^^^^^^^^^^^^^
  File "/lab/haoq_lab/cse12212635/.conda/envs/dl/lib/python3.11/multiprocessing/spawn.py", line 131, in _main
    prepare(preparation_data)
  File "/lab/haoq_lab/cse12212635/.conda/envs/dl/lib/python3.11/multiprocessing/spawn.py", line 246, in prepare
    _fixup_main_from_path(data['init_main_from_path'])
  File "/lab/haoq_lab/cse12212635/.conda/envs/dl/lib/python3.11/multiprocessing/spawn.py", line 297, in _fixup_main_from_path
    main_content = runpy.run_path(main_path,
                   ^^^^^^^^^^^^^^^^^^^^^^^^^
  File "<frozen runpy>", line 291, in run_path
  File "<frozen runpy>", line 98, in _run_module_code
  File "<frozen runpy>", line 88, in _run_code
  File "/lab/haoq_lab/cse12212635/slds_progect1/double_descent.py", line 16, in <module>
    from models.cnn import CNNBlock, CNNv4
  File "/lab/haoq_lab/cse12212635/slds_progect1/models/cnn.py", line 221
    
    ^
IndentationError: expected an indented block after class definition on line 220
Traceback (most recent call last):
  File "<string>", line 1, in <module>
  File "/lab/haoq_lab/cse12212635/.conda/envs/dl/lib/python3.11/multiprocessing/spawn.py", line 122, in spawn_main
    exitcode = _main(fd, parent_sentinel)
               ^^^^^^^^^^^^^^^^^^^^^^^^^^
  File "/lab/haoq_lab/cse12212635/.conda/envs/dl/lib/python3.11/multiprocessing/spawn.py", line 131, in _main
    prepare(preparation_data)
  File "/lab/haoq_lab/cse12212635/.conda/envs/dl/lib/python3.11/multiprocessing/spawn.py", line 246, in prepare
    _fixup_main_from_path(data['init_main_from_path'])
  File "/lab/haoq_lab/cse12212635/.conda/envs/dl/lib/python3.11/multiprocessing/spawn.py", line 297, in _fixup_main_from_path
    main_content = runpy.run_path(main_path,
                   ^^^^^^^^^^^^^^^^^^^^^^^^^
  File "<frozen runpy>", line 291, in run_path
  File "<frozen runpy>", line 98, in _run_module_code
  File "<frozen runpy>", line 88, in _run_code
  File "/lab/haoq_lab/cse12212635/slds_progect1/double_descent.py", line 16, in <module>
    from models.cnn import CNNBlock, CNNv4
  File "/lab/haoq_lab/cse12212635/slds_progect1/models/cnn.py", line 221
    
    ^
IndentationError: expected an indented block after class definition on line 220
[rank0]:[W519 03:36:20.289136457 ProcessGroupNCCL.cpp:1476] Warning: WARNING: destroy_process_group() was not called before program exit, which can leak resources. For more info, please see https://pytorch.org/docs/stable/distributed.html#shutdown (function operator())
[rank4]:[W519 03:36:21.738568140 TCPStore.cpp:125] [c10d] recvValue failed on SocketImpl(fd=38, addr=[localhost]:48756, remote=[localhost]:12375): failed to recv, got 0 bytes
Exception raised from recvBytes at /pytorch/torch/csrc/distributed/c10d/Utils.hpp:678 (most recent call first):
frame #0: c10::Error::Error(c10::SourceLocation, std::__cxx11::basic_string<char, std::char_traits<char>, std::allocator<char> >) + 0x98 (0x7fa0eccd95e8 in /lab/haoq_lab/cse12212635/.conda/envs/dl/lib/python3.11/site-packages/torch/lib/libc10.so)
frame #1: <unknown function> + 0x5ba8afe (0x7fa130dfcafe in /lab/haoq_lab/cse12212635/.conda/envs/dl/lib/python3.11/site-packages/torch/lib/libtorch_cpu.so)
frame #2: <unknown function> + 0x5baae40 (0x7fa130dfee40 in /lab/haoq_lab/cse12212635/.conda/envs/dl/lib/python3.11/site-packages/torch/lib/libtorch_cpu.so)
frame #3: <unknown function> + 0x5bab74a (0x7fa130dff74a in /lab/haoq_lab/cse12212635/.conda/envs/dl/lib/python3.11/site-packages/torch/lib/libtorch_cpu.so)
frame #4: c10d::TCPStore::check(std::vector<std::__cxx11::basic_string<char, std::char_traits<char>, std::allocator<char> >, std::allocator<std::__cxx11::basic_string<char, std::char_traits<char>, std::allocator<char> > > > const&) + 0x2a9 (0x7fa130df91a9 in /lab/haoq_lab/cse12212635/.conda/envs/dl/lib/python3.11/site-packages/torch/lib/libtorch_cpu.so)
frame #5: c10d::ProcessGroupNCCL::heartbeatMonitor() + 0x379 (0x7fa0edff29a9 in /lab/haoq_lab/cse12212635/.conda/envs/dl/lib/python3.11/site-packages/torch/lib/libtorch_cuda.so)
frame #6: <unknown function> + 0xdbbf4 (0x7fa0ddfbbbf4 in /lab/haoq_lab/cse12212635/.conda/envs/dl/bin/../lib/libstdc++.so.6)
frame #7: <unknown function> + 0x817a (0x7fa1560b117a in /lib64/libpthread.so.0)
frame #8: clone + 0x43 (0x7fa155656df3 in /lib64/libc.so.6)

[rank4]:[W519 03:36:21.743664935 ProcessGroupNCCL.cpp:1659] [PG ID 0 PG GUID 0(default_pg) Rank 4] Failed to check the "should dump" flag on TCPStore, (maybe TCPStore server has shut down too early), with error: failed to recv, got 0 bytes
[rank7]:[W519 03:36:21.867660819 TCPStore.cpp:125] [c10d] recvValue failed on SocketImpl(fd=39, addr=[localhost]:48764, remote=[localhost]:12375): failed to recv, got 0 bytes
Exception raised from recvBytes at /pytorch/torch/csrc/distributed/c10d/Utils.hpp:678 (most recent call first):
frame #0: c10::Error::Error(c10::SourceLocation, std::__cxx11::basic_string<char, std::char_traits<char>, std::allocator<char> >) + 0x98 (0x7fcc9cad95e8 in /lab/haoq_lab/cse12212635/.conda/envs/dl/lib/python3.11/site-packages/torch/lib/libc10.so)
frame #1: <unknown function> + 0x5ba8afe (0x7fcce0bfcafe in /lab/haoq_lab/cse12212635/.conda/envs/dl/lib/python3.11/site-packages/torch/lib/libtorch_cpu.so)
frame #2: <unknown function> + 0x5baae40 (0x7fcce0bfee40 in /lab/haoq_lab/cse12212635/.conda/envs/dl/lib/python3.11/site-packages/torch/lib/libtorch_cpu.so)
frame #3: <unknown function> + 0x5bab74a (0x7fcce0bff74a in /lab/haoq_lab/cse12212635/.conda/envs/dl/lib/python3.11/site-packages/torch/lib/libtorch_cpu.so)
frame #4: c10d::TCPStore::check(std::vector<std::__cxx11::basic_string<char, std::char_traits<char>, std::allocator<char> >, std::allocator<std::__cxx11::basic_string<char, std::char_traits<char>, std::allocator<char> > > > const&) + 0x2a9 (0x7fcce0bf91a9 in /lab/haoq_lab/cse12212635/.conda/envs/dl/lib/python3.11/site-packages/torch/lib/libtorch_cpu.so)
frame #5: c10d::ProcessGroupNCCL::heartbeatMonitor() + 0x379 (0x7fcc9ddf29a9 in /lab/haoq_lab/cse12212635/.conda/envs/dl/lib/python3.11/site-packages/torch/lib/libtorch_cuda.so)
frame #6: <unknown function> + 0xdbbf4 (0x7fcc8ddbbbf4 in /lab/haoq_lab/cse12212635/.conda/envs/dl/bin/../lib/libstdc++.so.6)
frame #7: <unknown function> + 0x817a (0x7fcd05eb117a in /lib64/libpthread.so.0)
frame #8: clone + 0x43 (0x7fcd05456df3 in /lib64/libc.so.6)

[rank7]:[W519 03:36:21.872859827 ProcessGroupNCCL.cpp:1659] [PG ID 0 PG GUID 0(default_pg) Rank 7] Failed to check the "should dump" flag on TCPStore, (maybe TCPStore server has shut down too early), with error: failed to recv, got 0 bytes
W0519 03:36:21.739000 2353294 site-packages/torch/multiprocessing/spawn.py:169] Terminating process 2353363 via signal SIGTERM
W0519 03:36:21.741000 2353294 site-packages/torch/multiprocessing/spawn.py:169] Terminating process 2353365 via signal SIGTERM
W0519 03:36:21.742000 2353294 site-packages/torch/multiprocessing/spawn.py:169] Terminating process 2353366 via signal SIGTERM
W0519 03:36:21.742000 2353294 site-packages/torch/multiprocessing/spawn.py:169] Terminating process 2353367 via signal SIGTERM
W0519 03:36:21.742000 2353294 site-packages/torch/multiprocessing/spawn.py:169] Terminating process 2353368 via signal SIGTERM
W0519 03:36:21.743000 2353294 site-packages/torch/multiprocessing/spawn.py:169] Terminating process 2353369 via signal SIGTERM
W0519 03:36:21.744000 2353294 site-packages/torch/multiprocessing/spawn.py:169] Terminating process 2353370 via signal SIGTERM
Traceback (most recent call last):
  File "/lab/haoq_lab/cse12212635/slds_progect1/double_descent.py", line 342, in <module>
    mp.spawn(
  File "/lab/haoq_lab/cse12212635/.conda/envs/dl/lib/python3.11/site-packages/torch/multiprocessing/spawn.py", line 340, in spawn
    return start_processes(fn, args, nprocs, join, daemon, start_method="spawn")
           ^^^^^^^^^^^^^^^^^^^^^^^^^^^^^^^^^^^^^^^^^^^^^^^^^^^^^^^^^^^^^^^^^^^^^
  File "/lab/haoq_lab/cse12212635/.conda/envs/dl/lib/python3.11/site-packages/torch/multiprocessing/spawn.py", line 296, in start_processes
    while not context.join():
              ^^^^^^^^^^^^^^
  File "/lab/haoq_lab/cse12212635/.conda/envs/dl/lib/python3.11/site-packages/torch/multiprocessing/spawn.py", line 215, in join
    raise ProcessRaisedException(msg, error_index, failed_process.pid)
torch.multiprocessing.spawn.ProcessRaisedException: 

-- Process 1 terminated with the following error:
Traceback (most recent call last):
  File "/lab/haoq_lab/cse12212635/.conda/envs/dl/lib/python3.11/site-packages/torch/utils/data/dataloader.py", line 1284, in _try_get_data
    data = self._data_queue.get(timeout=timeout)
           ^^^^^^^^^^^^^^^^^^^^^^^^^^^^^^^^^^^^^
  File "/lab/haoq_lab/cse12212635/.conda/envs/dl/lib/python3.11/queue.py", line 180, in get
    self.not_empty.wait(remaining)
  File "/lab/haoq_lab/cse12212635/.conda/envs/dl/lib/python3.11/threading.py", line 331, in wait
    gotit = waiter.acquire(True, timeout)
            ^^^^^^^^^^^^^^^^^^^^^^^^^^^^^
  File "/lab/haoq_lab/cse12212635/.conda/envs/dl/lib/python3.11/site-packages/torch/utils/data/_utils/signal_handling.py", line 73, in handler
    _error_if_any_worker_fails()
RuntimeError: DataLoader worker (pid 2938246) exited unexpectedly with exit code 1. Details are lost due to multiprocessing. Rerunning with num_workers=0 may give better error trace.

The above exception was the direct cause of the following exception:

Traceback (most recent call last):
  File "/lab/haoq_lab/cse12212635/.conda/envs/dl/lib/python3.11/site-packages/torch/multiprocessing/spawn.py", line 90, in _wrap
    fn(i, *args)
  File "/lab/haoq_lab/cse12212635/slds_progect1/double_descent.py", line 237, in main_worker
    train_loss = train_epoch_ddp(
                 ^^^^^^^^^^^^^^^^
  File "/lab/haoq_lab/cse12212635/slds_progect1/double_descent.py", line 46, in train_epoch_ddp
    for batch_idx, (data, target) in enumerate(train_loader):
  File "/lab/haoq_lab/cse12212635/.conda/envs/dl/lib/python3.11/site-packages/torch/utils/data/dataloader.py", line 733, in __next__
    data = self._next_data()
           ^^^^^^^^^^^^^^^^^
  File "/lab/haoq_lab/cse12212635/.conda/envs/dl/lib/python3.11/site-packages/torch/utils/data/dataloader.py", line 1491, in _next_data
    idx, data = self._get_data()
                ^^^^^^^^^^^^^^^^
  File "/lab/haoq_lab/cse12212635/.conda/envs/dl/lib/python3.11/site-packages/torch/utils/data/dataloader.py", line 1443, in _get_data
    success, data = self._try_get_data()
                    ^^^^^^^^^^^^^^^^^^^^
  File "/lab/haoq_lab/cse12212635/.conda/envs/dl/lib/python3.11/site-packages/torch/utils/data/dataloader.py", line 1297, in _try_get_data
    raise RuntimeError(
RuntimeError: DataLoader worker (pid(s) 2938246) exited unexpectedly

